#### 异步操作中使用try-catch无法捕获异常

```js
//异步操作中，使用try-catch是无法捕获异常的，只能使用内置的回调函数中的err参数
//对于异步操作，要通过判断错误(error.code)来进行处理错误
var fs = require('fs');
try {
				//没有这个路径的情况下
	fs.writeFile('./xx/abc/a.txt', '大家早上好！', 'utf8', (error) => {
		console.log('ok')		//try-catch 没用 还是输出了'ok'
	})
}
catch(e) {
	console.log('出错了' + e)
}
//上面是错误的， 应该是

var fs = require('fs');
fs.writeFile('./xx/abc/a.txt', '大家早上好！', 'utf8', (error) => {
	if(error) {
		console.log('出错了');
		throw error;
	}
	else {
		console.log('ok')
	}
})
```